Workbook

Sheet FY2025 - Forecast
A1: Account | B1: 45474 | C1: 45505 | D1: Sept 2024 | E1: 45566 | F1: 45597 | G1: 45627 | H1: 45658 | I1: 45689 | J1: 45717 | K1: 45748 | L1: 45778 | M1: 45809 | N1: FY2025 | Q1: 45839 | R1: 45870 | S1: 45901 | T1: 45931 | U1: 45962 | V1: 45992 | W1: 46023 | X1: 46054 | Y1: 46082 | Z1: 46113 | AA1: 46143 | AB1: 46174 | AC1: FY2025
B2: Actual | C2: Actual | D2: Actual | E2: Actual | F2: Actual | G2: Actual | H2: Actual | I2: Actual | J2: Actual | K2: Actual | L2: Actual | M2: Actual | N2: Actual | Q2: Forecast | R2: Forecast | S2: Forecast | T2: Forecast | U2: Forecast | V2: Forecast | W2: Forecast | X2: Forecast | Y2: Forecast | Z2: Forecast | AA2: Forecast | AB2: Forecast | AC2: Forecast
N4: =sum(B4:M4) -> 0 | AC4: =sum(Q4:AB4) -> 0
N5: =sum(B5:M5) -> 0 | AC5: =sum(Q5:AB5) -> 0
N6: =sum(B6:M6) -> 0 | AC6: =sum(Q6:AB6) -> 0
N7: =sum(B7:M7) -> 0 | AC7: =sum(Q7:AB7) -> 0
N8: =sum(B8:M8) -> 0 | AC8: =sum(Q8:AB8) -> 0
B9: =sum(B4:B8) -> 0 | C9: =sum(C4:C8) -> 0 | D9: =sum(D4:D8) -> 0 | E9: =sum(E4:E8) -> 0 | F9: =sum(F4:F8) -> 0 | G9: =sum(G4:G8) -> 0 | H9: =sum(H4:H8) -> 0 | I9: =sum(I4:I8) -> 0 | ... N9: =sum(N4:N8) -> 0 | Q9: =sum(Q4:Q8) -> 0 | R9: =sum(R4:R8) -> 0 | S9: =sum(S4:S8) -> 0 | T9: =sum(T4:T8) -> 0 | U9: =sum(U4:U8) -> 0 | V9: =sum(V4:V8) -> 0 | W9: =sum(W4:W8) -> 0 | X9: =sum(X4:X8) -> 0 | ... AC9: =sum(AC4:AC8) -> 0
N12: =sum(B12:M12) -> 0 | AC12: =sum(Q12:AB12) -> 0
N13: =sum(B13:M13) -> 0 | AC13: =sum(Q13:AB13) -> 0
N14: =sum(B14:M14) -> 0 | R14: =Payroll!I27 -> #REF! | S14: =Payroll!J27 -> #REF! | T14: =Payroll!K27 -> #REF! | U14: =Payroll!L27 -> #REF! | V14: =Payroll!M27 -> #REF! | W14: =Payroll!N27 -> #REF! | X14: =Payroll!O27 -> #REF! | Y14: =Payroll!P27 -> #REF! | ... AB14: =Payroll!S27 -> #REF! | AC14: =sum(Q14:AB14) -> #REF!
B15: =sum(B12:B14) -> 0 | C15: =sum(C12:C14) -> 0 | D15: =sum(D12:D14) -> 0 | E15: =sum(E12:E14) -> 0 | F15: =sum(F12:F14) -> 0 | G15: =sum(G12:G14) -> 0 | H15: =sum(H12:H14) -> 0 | I15: =sum(I12:I14) -> 0 | ... N15: =sum(N12:N14) -> 0 | Q15: =sum(Q12:Q14) -> 0 | R15: =sum(R12:R14) -> #REF! | S15: =sum(S12:S14) -> #REF! | T15: =sum(T12:T14) -> #REF! | U15: =sum(U12:U14) -> #REF! | V15: =sum(V12:V14) -> #REF! | W15: =sum(W12:W14) -> #REF! | X15: =sum(X12:X14) -> #REF! | ... AC15: =sum(AC12:AC14) -> #REF!
B17: =B9-B15 -> 0 | C17: =C9-C15 -> 0 | D17: =D9-D15 -> 0 | E17: =E9-E15 -> 0 | F17: =F9-F15 -> 0 | G17: =G9-G15 -> 0 | H17: =H9-H15 -> 0 | I17: =I9-I15 -> 0 | ... N17: =N9-N15 -> 0 | Q17: =Q9-Q15 -> 0 | R17: =R9-R15 -> #REF! | S17: =S9-S15 -> #REF! | T17: =T9-T15 -> #REF! | U17: =U9-U15 -> #REF! | V17: =V9-V15 -> #REF! | W17: =W9-W15 -> #REF! | X17: =X9-X15 -> #REF! | ... AC17: =AC9-AC15 -> #REF!
N20: =sum(B20:M20) -> 0 | AC20: =sum(Q20:AB20) -> 0
N21: =sum(B21:M21) -> 0 | AC21: =sum(Q21:AB21) -> 0
N22: =sum(B22:M22) -> 0 | AC22: =sum(Q22:AB22) -> 0
N23: =sum(B23:M23) -> 0 | AC23: =sum(Q23:AB23) -> 0
N24: =sum(B24:M24) -> 0 | AC24: =sum(Q24:AB24) -> 0
N25: =sum(B25:M25) -> 0 | AC25: =sum(Q25:AB25) -> 0
N26: =sum(B26:M26) -> 0 | AC26: =sum(Q26:AB26) -> 0
N27: =sum(B27:M27) -> 0 | AC27: =sum(Q27:AB27) -> 0
N28: =sum(B28:M28) -> 0 | AC28: =sum(Q28:AB28) -> 0
N29: =sum(B29:M29) -> 0 | AC29: =sum(Q29:AB29) -> 0
N30: =sum(B30:M30) -> 0 | AC30: =sum(Q30:AB30) -> 0
N31: =sum(B31:M31) -> 0 | AC31: =sum(Q31:AB31) -> 0
N32: =sum(B32:M32) -> 0 | Q32: =$P32 | R32: =$P32 | S32: =$P32 | T32: =$P32 | U32: =$P32 | V32: =$P32 | W32: =$P32 | X32: =$P32 | ... AB32: =$P32 | AC32: =sum(Q32:AB32) -> 0
N33: =sum(B33:M33) -> 0 | Q33: =$P33 | R33: =$P33 | S33: =$P33 | T33: =$P33 | U33: =$P33 | V33: =$P33 | W33: =$P33 | X33: =$P33 | ... AB33: =$P33 | AC33: =sum(Q33:AB33) -> 0
N34: =sum(B34:M34) -> 0 | Q34: =$P34 | R34: =$P34 | S34: =$P34 | T34: =$P34 | U34: =$P34 | V34: =$P34 | W34: =$P34 | X34: =$P34 | ... AB34: =$P34 | AC34: =sum(Q34:AB34) -> 0
N35: =sum(B35:M35) -> 0 | Q35: =$P35 | R35: =$P35 | S35: =$P35 | T35: =$P35 | U35: =$P35 | V35: =$P35 | W35: =$P35 | X35: =$P35 | ... AB35: =$P35 | AC35: =sum(Q35:AB35) -> 0
N36: =sum(B36:M36) -> 0 | Q36: =$P36 | R36: =$P36 | S36: =$P36 | T36: =$P36 | U36: =$P36 | V36: =$P36 | W36: =$P36 | X36: =$P36 | ... AB36: =$P36 | AC36: =sum(Q36:AB36) -> 0
N37: =sum(B37:M37) -> 0 | Q37: =$P37 | R37: =$P37 | S37: =$P37 | T37: =$P37 | U37: =$P37 | V37: =$P37 | W37: =$P37 | X37: =$P37 | ... AB37: =$P37 | AC37: =sum(Q37:AB37) -> 0
N38: =sum(B38:M38) -> 0 | Q38: =$P38 | R38: =$P38 | S38: =$P38 | T38: =$P38 | U38: =$P38 | V38: =$P38 | W38: =$P38 | X38: =$P38 | ... AB38: =$P38 | AC38: =sum(Q38:AB38) -> 0
N39: =sum(B39:M39) -> 0 | AC39: =sum(Q39:AB39) -> 0
N40: =sum(B40:M40) -> 0 | AC40: =sum(Q40:AB40) -> 0
N41: =sum(B41:M41) -> 0 | AC41: =sum(Q41:AB41) -> 0
N42: =sum(B42:M42) -> 0 | AC42: =sum(Q42:AB42) -> 0
N43: =sum(B43:M43) -> 0 | AC43: =sum(Q43:AB43) -> 0
N44: =sum(B44:M44) -> 0 | AC44: =sum(Q44:AB44) -> 0
N45: =sum(B45:M45) -> 0 | AC45: =sum(Q45:AB45) -> 0
N46: =sum(B46:M46) -> 0 | AC46: =sum(Q46:AB46) -> 0
...

Sheet Payroll
B1: Employee Name | C1: Category | D1: Star Date | E1: End Date | F1: Hours | G1: Rate | H1: Weekly Budget | I1: Annual Salary | K1: Weekly PAYG
C2: Wages Admin | K2: =IF($I2<=18200,0,IF($I2<=45000,($I2-18200)*0.19,IF($I2<=120000,($I2-45000)*0.325+5092,IF($I2<=180000,($I2-120000)*0.37+29467,IF($I2>180000,($I2-180000)*0.45+51667)))))/52 -> 0
C3: Wages Admin | K3: =IF($I3<=18200,0,IF($I3<=45000,($I3-18200)*0.19,IF($I3<=120000,($I3-45000)*0.325+5092,IF($I3<=180000,($I3-120000)*0.37+29467,IF($I3>180000,($I3-180000)*0.45+51667)))))/52 -> 0
C4: Wages COGS | K4: =IF($I4<=18200,0,IF($I4<=45000,($I4-18200)*0.19,IF($I4<=120000,($I4-45000)*0.325+5092,IF($I4<=180000,($I4-120000)*0.37+29467,IF($I4>180000,($I4-180000)*0.45+51667)))))/52 -> 0
C5: Wages COGS | K5: =IF($I5<=18200,0,IF($I5<=45000,($I5-18200)*0.19,IF($I5<=120000,($I5-45000)*0.325+5092,IF($I5<=180000,($I5-120000)*0.37+29467,IF($I5>180000,($I5-180000)*0.45+51667)))))/52 -> 0
K6: =IF($I6<=18200,0,IF($I6<=45000,($I6-18200)*0.19,IF($I6<=120000,($I6-45000)*0.325+5092,IF($I6<=180000,($I6-120000)*0.37+29467,IF($I6>180000,($I6-180000)*0.45+51667)))))/52 -> 0
K7: =IF($I7<=18200,0,IF($I7<=45000,($I7-18200)*0.19,IF($I7<=120000,($I7-45000)*0.325+5092,IF($I7<=180000,($I7-120000)*0.37+29467,IF($I7>180000,($I7-180000)*0.45+51667)))))/52 -> 0
K8: =IF($I8<=18200,0,IF($I8<=45000,($I8-18200)*0.19,IF($I8<=120000,($I8-45000)*0.325+5092,IF($I8<=180000,($I8-120000)*0.37+29467,IF($I8>180000,($I8-180000)*0.45+51667)))))/52 -> 0
K9: =IF($I9<=18200,0,IF($I9<=45000,($I9-18200)*0.19,IF($I9<=120000,($I9-45000)*0.325+5092,IF($I9<=180000,($I9-120000)*0.37+29467,IF($I9>180000,($I9-180000)*0.45+51667)))))/52 -> 0
K10: =IF($I10<=18200,0,IF($I10<=45000,($I10-18200)*0.19,IF($I10<=120000,($I10-45000)*0.325+5092,IF($I10<=180000,($I10-120000)*0.37+29467,IF($I10>180000,($I10-180000)*0.45+51667)))))/52 -> 0
K11: =IF($I11<=18200,0,IF($I11<=45000,($I11-18200)*0.19,IF($I11<=120000,($I11-45000)*0.325+5092,IF($I11<=180000,($I11-120000)*0.37+29467,IF($I11>180000,($I11-180000)*0.45+51667)))))/52 -> 0
K12: =IF($I12<=18200,0,IF($I12<=45000,($I12-18200)*0.19,IF($I12<=120000,($I12-45000)*0.325+5092,IF($I12<=180000,($I12-120000)*0.37+29467,IF($I12>180000,($I12-180000)*0.45+51667)))))/52 -> 0
K13: =IF($I13<=18200,0,IF($I13<=45000,($I13-18200)*0.19,IF($I13<=120000,($I13-45000)*0.325+5092,IF($I13<=180000,($I13-120000)*0.37+29467,IF($I13>180000,($I13-180000)*0.45+51667)))))/52 -> 0
K14: =IF($I14<=18200,0,IF($I14<=45000,($I14-18200)*0.19,IF($I14<=120000,($I14-45000)*0.325+5092,IF($I14<=180000,($I14-120000)*0.37+29467,IF($I14>180000,($I14-180000)*0.45+51667)))))/52 -> 0
K15: =IF($I15<=18200,0,IF($I15<=45000,($I15-18200)*0.19,IF($I15<=120000,($I15-45000)*0.325+5092,IF($I15<=180000,($I15-120000)*0.37+29467,IF($I15>180000,($I15-180000)*0.45+51667)))))/52 -> 0
K16: =IF($I16<=18200,0,IF($I16<=45000,($I16-18200)*0.19,IF($I16<=120000,($I16-45000)*0.325+5092,IF($I16<=180000,($I16-120000)*0.37+29467,IF($I16>180000,($I16-180000)*0.45+51667)))))/52 -> 0
K17: =IF($I17<=18200,0,IF($I17<=45000,($I17-18200)*0.19,IF($I17<=120000,($I17-45000)*0.325+5092,IF($I17<=180000,($I17-120000)*0.37+29467,IF($I17>180000,($I17-180000)*0.45+51667)))))/52 -> 0
K18: =IF($I18<=18200,0,IF($I18<=45000,($I18-18200)*0.19,IF($I18<=120000,($I18-45000)*0.325+5092,IF($I18<=180000,($I18-120000)*0.37+29467,IF($I18>180000,($I18-180000)*0.45+51667)))))/52 -> 0
H25: # of PayRuns | I25: 5 | J25: 4 | K25: 5 | L25: 4 | M25: 4 | N25: 5 | O25: 4 | P25: 4 | Q25: 5 | R25: 4 | S25: 4 | T25: 4
H26: FY2025 | I26: 45504 | J26: 45535 | K26: 45565 | L26: 45596 | M26: 45626 | N26: 45657 | O26: 45688 | P26: 45716 | Q26: 45747 | R26: 45777 | S26: 45808 | T26: 45838
H27: Wages Admin | I27: =(SUMIFS($H$2:$H$18,$C$2:$C$18,$H$27,$D$2:$D$18,"<="&I26)-SUMIFS($H$2:$H$18,$C$2:$C$18,$H$27,$E$2:$E$18,"<="&I26))*I25 -> 0 | J27: =(SUMIFS($H$2:$H$18,$C$2:$C$18,$H$27,$D$2:$D$18,"<="&J26)-SUMIFS($H$2:$H$18,$C$2:$C$18,$H$27,$E$2:$E$18,"<="&J26))*J25 -> 0 | K27: =(SUMIFS($H$2:$H$18,$C$2:$C$18,$H$27,$D$2:$D$18,"<="&K26)-SUMIFS($H$2:$H$18,$C$2:$C$18,$H$27,$E$2:$E$18,"<="&K26))*K25 -> 0 | L27: =(SUMIFS($H$2:$H$18,$C$2:$C$18,$H$27,$D$2:$D$18,"<="&L26)-SUMIFS($H$2:$H$18,$C$2:$C$18,$H$27,$E$2:$E$18,"<="&L26))*L25 -> 0 | M27: =(SUMIFS($H$2:$H$18,$C$2:$C$18,$H$27,$D$2:$D$18,"<="&M26)-SUMIFS($H$2:$H$18,$C$2:$C$18,$H$27,$E$2:$E$18,"<="&M26))*M25 -> 0 | N27: =(SUMIFS($H$2:$H$18,$C$2:$C$18,$H$27,$D$2:$D$18,"<="&N26)-SUMIFS($H$2:$H$18,$C$2:$C$18,$H$27,$E$2:$E$18,"<="&N26))*N25 -> 0 | O27: =(SUMIFS($H$2:$H$18,$C$2:$C$18,$H$27,$D$2:$D$18,"<="&O26)-SUMIFS($H$2:$H$18,$C$2:$C$18,$H$27,$E$2:$E$18,"<="&O26))*O25 -> 0 | P27: =(SUMIFS($H$2:$H$18,$C$2:$C$18,$H$27,$D$2:$D$18,"<="&P26)-SUMIFS($H$2:$H$18,$C$2:$C$18,$H$27,$E$2:$E$18,"<="&P26))*P25 -> 0 | ... T27: =(SUMIFS($H$2:$H$18,$C$2:$C$18,$H$27,$D$2:$D$18,"<="&T26)-SUMIFS($H$2:$H$18,$C$2:$C$18,$H$27,$E$2:$E$18,"<="&T26))*T25 -> 0
H28: Wages COGS | I28: =(SUMIFS($H$2:$H$18,$C$2:$C$18,$H$28,$D$2:$D$18,"<="&I26)-SUMIFS($H$2:$H$18,$C$2:$C$18,$H$28,$E$2:$E$18,"<="&I26))*I25 -> 0 | J28: =(SUMIFS($H$2:$H$18,$C$2:$C$18,$H$28,$D$2:$D$18,"<="&J26)-SUMIFS($H$2:$H$18,$C$2:$C$18,$H$28,$E$2:$E$18,"<="&J26))*J25 -> 0 | K28: =(SUMIFS($H$2:$H$18,$C$2:$C$18,$H$28,$D$2:$D$18,"<="&K26)-SUMIFS($H$2:$H$18,$C$2:$C$18,$H$28,$E$2:$E$18,"<="&K26))*K25 -> 0 | L28: =(SUMIFS($H$2:$H$18,$C$2:$C$18,$H$28,$D$2:$D$18,"<="&L26)-SUMIFS($H$2:$H$18,$C$2:$C$18,$H$28,$E$2:$E$18,"<="&L26))*L25 -> 0 | M28: =(SUMIFS($H$2:$H$18,$C$2:$C$18,$H$28,$D$2:$D$18,"<="&M26)-SUMIFS($H$2:$H$18,$C$2:$C$18,$H$28,$E$2:$E$18,"<="&M26))*M25 -> 0 | N28: =(SUMIFS($H$2:$H$18,$C$2:$C$18,$H$28,$D$2:$D$18,"<="&N26)-SUMIFS($H$2:$H$18,$C$2:$C$18,$H$28,$E$2:$E$18,"<="&N26))*N25 -> 0 | O28: =(SUMIFS($H$2:$H$18,$C$2:$C$18,$H$28,$D$2:$D$18,"<="&O26)-SUMIFS($H$2:$H$18,$C$2:$C$18,$H$28,$E$2:$E$18,"<="&O26))*O25 -> 0 | P28: =(SUMIFS($H$2:$H$18,$C$2:$C$18,$H$28,$D$2:$D$18,"<="&P26)-SUMIFS($H$2:$H$18,$C$2:$C$18,$H$28,$E$2:$E$18,"<="&P26))*P25 -> 0 | ... T28: =(SUMIFS($H$2:$H$18,$C$2:$C$18,$H$28,$D$2:$D$18,"<="&T26)-SUMIFS($H$2:$H$18,$C$2:$C$18,$H$28,$E$2:$E$18,"<="&T26))*T25 -> 0
H29: PAYG
H30: Net Wages | I30: =I28-I29 -> 0 | J30: =J28-J29 -> 0 | K30: =K28-K29 -> 0 | L30: =L28-L29 -> 0 | M30: =M28-M29 -> 0 | N30: =N28-N29 -> 0 | O30: =O28-O29 -> 0 | P30: =P28-P29 -> 0 | ... T30: =T28-T29 -> 0
H31: Superannuation | I31: =I28*11.5% -> 0 | J31: =J28*11.5% -> 0 | K31: =K28*11.5% -> 0 | L31: =L28*11.5% -> 0 | M31: =M28*11.5% -> 0 | N31: =N28*11.5% -> 0 | O31: =O28*11.5% -> 0 | P31: =P28*11.5% -> 0 | ... T31: =T28*11.5% -> 0
H32: Payroll Tax
