Workbook
Name zone: 'Step 2- Activity Inventory'!$AR$3:$AS$7

Sheet Basic Time Log
B2: The Stop Doing List
B4: Basic Time Log
B6: In order to understand what you need to "Stop Doing" you must get a clear understanding of what you currently do. | H6: Week Totals
B7: Keep a time log for a minimum of 2 weeks to understand where you are currently investing/spending your time. | H7: Mins | I7: Hours
B8: Watch the video to understand how to use the time log tool. | H8: =COUNTA($C$13:$I$63)*0.25*60 -> 0 | I8: =H8/60 -> 0
B10: Time Log | C10: Monday | D10: Tuesday | E10: Wednesday | F10: Thursday | G10: Friday | H10: Saturday | I10: Sunday
B13: 0500:0515
B14: 0515:0530
B15: 0530:0545
B16: 0545:0600
B17: 0600:0615
B18: 0615:0630
B19: 0630:0645
B20: 0645:0700
B21: 0700:0715
B22: 0715:0730
B23: 0730:0745
B24: 0745:0800
... B79: 2145:2200

Sheet Advanced Time Log
B2: The Stop Doing List
B4: Advanced Time Log
B6: In order to understand what you need to "Stop Doing" you must get a clear understanding of what you currently do.
B7: Keep a time log for a minimum of 2 weeks to understand where you are currently investing/spending your time.
B8: Watch the video to understand how to use the time log tool.
B10: Time Log | C10: Monday | D10: Tuesday | E10: Wednesday | F10: Thursday | G10: Friday | H10: Saturday | I10: Sunday | K10: Category | L10: Initial/Code | M10: Week Total | O10: % Business | P10: % Total
K11: Business | M11: Mins | N11: Hrs
B13: 0500:0515 | K13: Administration | L13: Admin | M13: =(COUNTIF($C$13:$I$63,$L13)*0.25)*60 -> 0 | N13: =M13/60 -> 0 | O13: =IFERROR(M13/$M$26,"0%") -> 0% | P13: =IFERROR(M13/$M$42,"0%") -> 0% | BY13: =IF(L13="","",L13) -> Admin
B14: 0515:0530 | K14: Delivering Service | L14: Delivery | M14: =(COUNTIF($C$13:$I$63,$L14)*0.25)*60 -> 0 | N14: =M14/60 -> 0 | O14: =IFERROR(M14/$M$26,"0%") -> 0% | P14: =IFERROR(M14/$M$42,"0%") -> 0% | BY14: =IF(L14="","",L14) -> Delivery
B15: 0530:0545 | K15: Sales | L15: Sales | M15: =(COUNTIF($C$13:$I$63,$L15)*0.25)*60 -> 0 | N15: =M15/60 -> 0 | O15: =IFERROR(M15/$M$26,"0%") -> 0% | P15: =IFERROR(M15/$M$42,"0%") -> 0% | BY15: =IF(L15="","",L15) -> Sales
B16: 0545:0600 | K16: Marketing | L16: MKT | M16: =(COUNTIF($C$13:$I$63,$L16)*0.25)*60 -> 0 | N16: =M16/60 -> 0 | O16: =IFERROR(M16/$M$26,"0%") -> 0% | P16: =IFERROR(M16/$M$42,"0%") -> 0% | BY16: =IF(L16="","",L16) -> MKT
B17: 0600:0615 | K17: Human Resources | L17: HR | M17: =(COUNTIF($C$13:$I$63,$L17)*0.25)*60 -> 0 | N17: =M17/60 -> 0 | O17: =IFERROR(M17/$M$26,"0%") -> 0% | P17: =IFERROR(M17/$M$42,"0%") -> 0% | BY17: =IF(L17="","",L17) -> HR
B18: 0615:0630 | K18: Meeting Internal | L18: Meeting Int | M18: =(COUNTIF($C$13:$I$63,$L18)*0.25)*60 -> 0 | N18: =M18/60 -> 0 | O18: =IFERROR(M18/$M$26,"0%") -> 0% | P18: =IFERROR(M18/$M$42,"0%") -> 0% | BY18: =IF(L18="","",L18) -> Meeting Int
B19: 0630:0645 | K19: Meeting External | L19: Meeting Ext | M19: =(COUNTIF($C$13:$I$63,$L19)*0.25)*60 -> 0 | N19: =M19/60 -> 0 | O19: =IFERROR(M19/$M$26,"0%") -> 0% | P19: =IFERROR(M19/$M$42,"0%") -> 0% | BY19: =IF(L19="","",L19) -> Meeting Ext
B20: 0645:0700 | K20: Training | L20: Training | M20: =(COUNTIF($C$13:$I$63,$L20)*0.25)*60 -> 0 | N20: =M20/60 -> 0 | O20: =IFERROR(M20/$M$26,"0%") -> 0% | P20: =IFERROR(M20/$M$42,"0%") -> 0% | BY20: =IF(L20="","",L20) -> Training
B21: 0700:0715 | K21: Emails | L21: Emails | M21: =(COUNTIF($C$13:$I$63,$L21)*0.25)*60 -> 0 | N21: =M21/60 -> 0 | O21: =IFERROR(M21/$M$26,"0%") -> 0% | P21: =IFERROR(M21/$M$42,"0%") -> 0% | BY21: =IF(L21="","",L21) -> Emails
B22: 0715:0730 | K22: Operations | L22: Ops | M22: =(COUNTIF($C$13:$I$63,$L22)*0.25)*60 -> 0 | N22: =M22/60 -> 0 | O22: =IFERROR(M22/$M$26,"0%") -> 0% | P22: =IFERROR(M22/$M$42,"0%") -> 0% | BY22: =IF(L22="","",L22) -> Ops
B23: 0730:0745 | K23: Business Coaching | L23: Coach | M23: =(COUNTIF($C$13:$I$63,$L23)*0.25)*60 -> 0 | N23: =M23/60 -> 0 | O23: =IFERROR(M23/$M$26,"0%") -> 0% | P23: =IFERROR(M23/$M$42,"0%") -> 0% | BY23: =IF(L23="","",L23) -> Coach
B24: 0745:0800 | K24: Blank Space 3 - Business | L24: Blank3B | M24: =(COUNTIF($C$13:$I$63,$L24)*0.25)*60 -> 0 | N24: =M24/60 -> 0 | O24: =IFERROR(M24/$M$26,"0%") -> 0% | P24: =IFERROR(M24/$M$42,"0%") -> 0% | BY24: =IF(L24="","",L24) -> Blank3B
B25: 0800:0815 | K25: Blank Space 4 - Business | L25: Blank4B | M25: =(COUNTIF($C$13:$I$63,$L25)*0.25)*60 -> 0 | N25: =M25/60 -> 0 | O25: =IFERROR(M25/$M$26,"0%") -> 0% | P25: =IFERROR(M25/$M$42,"0%") -> 0% | BY25: =IF(L25="","",L25) -> Blank4B
B26: 0815:0830 | K26: Sub Total | M26: =SUM(M13:M25) -> 0 | N26: =M26/60 -> 0 | O26: =IFERROR(M26/$M$42,"0%") -> 0% | BY26: =L30 -> EX
B27: 0830:0845 | BY27: =L31 -> FT
B28: 0845:0900 | K28: Category | L28: Initial/Code | M28: Week Total | N28: Week Total | O28: % Personal | P28: % Total | BY28: =L32 -> DN
B29: 0900:0915 | K29: Personal | L29: Initial/Code | M29: Mins | N29: Hrs | BY29: =L33 -> Ritual
B30: 0915:0930 | K30: Exercise | L30: EX | M30: =(COUNTIF($C$13:$I$79,$L30)*0.25)*60 -> 0 | N30: =M30/60 -> 0 | O30: =IFERROR(M30/$M$40,"0%") -> 0% | P30: =IFERROR(M30/$M$42,"0%") -> 0% | BY30: =L34 -> Sleep
B31: 0930:0945 | K31: Family Time | L31: FT | M31: =(COUNTIF($C$13:$I$79,$L31)*0.25)*60 -> 0 | N31: =M31/60 -> 0 | O31: =IFERROR(M31/$M$40,"0%") -> 0% | P31: =IFERROR(M31/$M$42,"0%") -> 0% | BY31: =L35 -> Rest
B32: 0945:1000 | K32: Date Night | L32: DN | M32: =(COUNTIF($C$13:$I$79,$L32)*0.25)*60 -> 0 | N32: =M32/60 -> 0 | O32: =IFERROR(M32/$M$40,"0%") -> 0% | P32: =IFERROR(M32/$M$42,"0%") -> 0% | BY32: =L36 -> Blank1P
B33: 1000:1015 | K33: Daily Ritual | L33: Ritual | M33: =(COUNTIF($C$13:$I$79,$L33)*0.25)*60 -> 0 | N33: =M33/60 -> 0 | O33: =IFERROR(M33/$M$40,"0%") -> 0% | P33: =IFERROR(M33/$M$42,"0%") -> 0% | BY33: =L37 -> Blank2P
B34: 1015:1030 | K34: Sleep | L34: Sleep | M34: =(COUNTIF($C$13:$I$79,$L34)*0.25)*60 -> 0 | N34: =M34/60 -> 0 | O34: =IFERROR(M34/$M$40,"0%") -> 0% | P34: =IFERROR(M34/$M$42,"0%") -> 0% | BY34: =L38 -> Blank3P
B35: 1030:1045 | K35: Rest | L35: Rest | M35: =(COUNTIF($C$13:$I$79,$L35)*0.25)*60 -> 0 | N35: =M35/60 -> 0 | O35: =IFERROR(M35/$M$40,"0%") -> 0% | P35: =IFERROR(M35/$M$42,"0%") -> 0% | BY35: =L39 -> Blank4P
B36: 1045:1100 | K36: Blank Space 1 - Personal | L36: Blank1P | M36: =(COUNTIF($C$13:$I$79,$L36)*0.25)*60 -> 0 | N36: =M36/60 -> 0 | O36: =IFERROR(M36/$M$40,"0%") -> 0% | P36: =IFERROR(M36/$M$42,"0%") -> 0%
B37: 1100:1115 | K37: Blank Space 2 - Personal | L37: Blank2P | M37: =(COUNTIF($C$13:$I$79,$L37)*0.25)*60 -> 0 | N37: =M37/60 -> 0 | O37: =IFERROR(M37/$M$40,"0%") -> 0% | P37: =IFERROR(M37/$M$42,"0%") -> 0%
B38: 1115:1130 | K38: Blank Space 3 - Personal | L38: Blank3P | M38: =(COUNTIF($C$13:$I$79,$L38)*0.25)*60 -> 0 | N38: =M38/60 -> 0 | O38: =IFERROR(M38/$M$40,"0%") -> 0% | P38: =IFERROR(M38/$M$42,"0%") -> 0%
B39: 1130:1145 | K39: Blank Space 4 - Personal | L39: Blank4P | M39: =(COUNTIF($C$13:$I$79,$L39)*0.25)*60 -> 0 | N39: =M39/60 -> 0 | O39: =IFERROR(M39/$M$40,"0%") -> 0% | P39: =IFERROR(M39/$M$42,"0%") -> 0%
B40: 1145:1200 | K40: Sub Total | M40: =SUM(M30:M39) -> 0 | N40: =M40/60 -> 0 | O40: =IFERROR(M40/$M$42,"0%") -> 0%
B41: 1200:1215
B42: 1215:1230 | K42: Total | M42: =M26+M40 -> 0 | N42: =M42/60 -> 0
B43: 1230:1245
B44: 1245:1300
B45: 1300:1315
...

Sheet Step 1- Hrly Rate Calc
B2: STEP 1
B4: Calculating your hourly rate
B6: Calculating your hourly rate provides a benchmark for you to measure against. Tasks that can be performed for an investment less than your hourly rate should be delegated internally, outsourced or eliminated.
B10: To calculate your hourly rate simply follow the 3 easy steps below:
B12: A. How much money do you want to make in the next 12 months (include money you would like to pay yourself a wage/salary plus dividends)
B14: B. Determine the number of weeks you intend working in the next 12 months (i.e. 52 - # of weeks holidays)
B16: C. Determine the total hours you intend working per week
B17: A ÷ B ÷ C = Hrly Rate
D18: =IFERROR(D12/D14/D16,"$0.00") -> $0.00

Sheet Step 2- Activity Inventory
B2: STEP 2 | AD2: Daily | AE2: Incompentence | AG2: Great Financial Return: I am really good at this task, I love doing it and want to KEEP doing it. | AH2: Eliminate | AR2: Description | AS2: Genius Zone Category
AD3: Weekly | AE3: Competence | AG3: Great Financial Return: I am really good at this task, I don’t love doing it but need to KEEP doing it. | AH3: Automate | AR3: Great Financial Return: I am really good at this task, I love doing it and want to KEEP doing it. | AS3: Genius
B4: Activity Inventory | AD4: Monthly | AE4: Excellence | AG4: Great Financial Return: I am really good at this task, I don’t love doing it and want to STOP doing it. | AH4: Delegate | AR4: Great Financial Return: I am really good at this task, I don’t love doing it but need to KEEP doing it. | AS4: Excellence
AD5: Quarterly | AE5: Genius | AG5: Low Financial Return: Requires the task drains me of energy and I resist doing it. | AR5: Great Financial Return: I am really good at this task, I don’t love doing it and want to STOP doing it. | AS5: Excellence
B6: Brainstorm and list all the tasks you perform or wish you had the time to perform in your business in the space below. Use these words to trigger you: Yesterday, Last Week, Monthly, Marketing, Sales, Content, Clients, Team, Admin, Finance | AD6: Other | AG6: Unsure of Financial Return, I know I need to do this task but don’t know how. | AR6: Low Financial Return: Requires the task drains me of energy and I resist doing it. | AS6: Competence
AR7: Unsure of Financial Return, I know I need to do this task but don’t know how. | AS7: Incompetence
B9: Task | C9: Frequency | D9: How long does this task take? (mins) | E9: Description | F9: Zone (automatic) | G9: Focus Funnel Outcome
F11: =IF(E11="","",IFERROR(VLOOKUP(E11,zone,2,0),"")) | I11: =IF(B11="",0,1) -> 0 | J11: =IF(C11="",0,1) -> 0 | K11: =IF(D11="",0,1) -> 0 | L11: =IF(E11="",0,1) -> 0 | M11: =IF(F11="",0,1) -> 0 | N11: =IF(G11="",0,1) -> 0 | O11: =SUM(I11:N11) -> 0
F12: =IF(E12="","",IFERROR(VLOOKUP(E12,zone,2,0),"")) | I12: =IF(B12="",0,1) -> 0 | J12: =IF(C12="",0,1) -> 0 | K12: =IF(D12="",0,1) -> 0 | L12: =IF(E12="",0,1) -> 0 | M12: =IF(F12="",0,1) -> 0 | N12: =IF(G12="",0,1) -> 0 | O12: =SUM(I12:N12) -> 0
F13: =IF(E13="","",IFERROR(VLOOKUP(E13,zone,2,0),"")) | I13: =IF(B13="",0,1) -> 0 | J13: =IF(C13="",0,1) -> 0 | K13: =IF(D13="",0,1) -> 0 | L13: =IF(E13="",0,1) -> 0 | M13: =IF(F13="",0,1) -> 0 | N13: =IF(G13="",0,1) -> 0 | O13: =SUM(I13:N13) -> 0
F14: =IF(E14="","",IFERROR(VLOOKUP(E14,zone,2,0),"")) | I14: =IF(B14="",0,1) -> 0 | J14: =IF(C14="",0,1) -> 0 | K14: =IF(D14="",0,1) -> 0 | L14: =IF(E14="",0,1) -> 0 | M14: =IF(F14="",0,1) -> 0 | N14: =IF(G14="",0,1) -> 0 | O14: =SUM(I14:N14) -> 0
F15: =IF(E15="","",IFERROR(VLOOKUP(E15,zone,2,0),"")) | I15: =IF(B15="",0,1) -> 0 | J15: =IF(C15="",0,1) -> 0 | K15: =IF(D15="",0,1) -> 0 | L15: =IF(E15="",0,1) -> 0 | M15: =IF(F15="",0,1) -> 0 | N15: =IF(G15="",0,1) -> 0 | O15: =SUM(I15:N15) -> 0
F16: =IF(E16="","",IFERROR(VLOOKUP(E16,zone,2,0),"")) | I16: =IF(B16="",0,1) -> 0 | J16: =IF(C16="",0,1) -> 0 | K16: =IF(D16="",0,1) -> 0 | L16: =IF(E16="",0,1) -> 0 | M16: =IF(F16="",0,1) -> 0 | N16: =IF(G16="",0,1) -> 0 | O16: =SUM(I16:N16) -> 0
F17: =IF(E17="","",IFERROR(VLOOKUP(E17,zone,2,0),"")) | I17: =IF(B17="",0,1) -> 0 | J17: =IF(C17="",0,1) -> 0 | K17: =IF(D17="",0,1) -> 0 | L17: =IF(E17="",0,1) -> 0 | M17: =IF(F17="",0,1) -> 0 | N17: =IF(G17="",0,1) -> 0 | O17: =SUM(I17:N17) -> 0
F18: =IF(E18="","",IFERROR(VLOOKUP(E18,zone,2,0),"")) | I18: =IF(B18="",0,1) -> 0 | J18: =IF(C18="",0,1) -> 0 | K18: =IF(D18="",0,1) -> 0 | L18: =IF(E18="",0,1) -> 0 | M18: =IF(F18="",0,1) -> 0 | N18: =IF(G18="",0,1) -> 0 | O18: =SUM(I18:N18) -> 0
F19: =IF(E19="","",IFERROR(VLOOKUP(E19,zone,2,0),"")) | I19: =IF(B19="",0,1) -> 0 | J19: =IF(C19="",0,1) -> 0 | K19: =IF(D19="",0,1) -> 0 | L19: =IF(E19="",0,1) -> 0 | M19: =IF(F19="",0,1) -> 0 | N19: =IF(G19="",0,1) -> 0 | O19: =SUM(I19:N19) -> 0
F20: =IF(E20="","",IFERROR(VLOOKUP(E20,zone,2,0),"")) | I20: =IF(B20="",0,1) -> 0 | J20: =IF(C20="",0,1) -> 0 | K20: =IF(D20="",0,1) -> 0 | L20: =IF(E20="",0,1) -> 0 | M20: =IF(F20="",0,1) -> 0 | N20: =IF(G20="",0,1) -> 0 | O20: =SUM(I20:N20) -> 0
F21: =IF(E21="","",IFERROR(VLOOKUP(E21,zone,2,0),"")) | I21: =IF(B21="",0,1) -> 0 | J21: =IF(C21="",0,1) -> 0 | K21: =IF(D21="",0,1) -> 0 | L21: =IF(E21="",0,1) -> 0 | M21: =IF(F21="",0,1) -> 0 | N21: =IF(G21="",0,1) -> 0 | O21: =SUM(I21:N21) -> 0
F22: =IF(E22="","",IFERROR(VLOOKUP(E22,zone,2,0),"")) | I22: =IF(B22="",0,1) -> 0 | J22: =IF(C22="",0,1) -> 0 | K22: =IF(D22="",0,1) -> 0 | L22: =IF(E22="",0,1) -> 0 | M22: =IF(F22="",0,1) -> 0 | N22: =IF(G22="",0,1) -> 0 | O22: =SUM(I22:N22) -> 0
... F500: =IF(E500="","",IFERROR(VLOOKUP(E500,zone,2,0),"")) | I500: =IF(B500="",0,1) -> 0 | J500: =IF(C500="",0,1) -> 0 | K500: =IF(D500="",0,1) -> 0 | L500: =IF(E500="",0,1) -> 0 | M500: =IF(F500="",0,1) -> 0 | N500: =IF(G500="",0,1) -> 0 | O500: =SUM(I500:N500) -> 0

Sheet Step 3 - Your Stop Doing List 
B2: STEP 3 | BE2: Low | BF2: Yes
BE3: Med | BF3: No
B4: Your Stop Doing List | BE4: High
B6: Task | C6: Frequency | D6: Description | E6: Zone | F6: Focus Funnel Outcome | G6: How long does this task take? (mins) | H6: Special Skills Required | I6: Task Importance (Low/Med/High) | J6: Is there a system for this task? | K6: Hourly Rate Investment for Someone Else to do this task | L6: My Hourly Rate | M6: Net Gain/Loss | N6: Opportunity Cost if you continue to do this task (Per annum) | O6: Suggested Decision | P6: Are you Ready To Stop Doing?
B8: =IF('Step 2- Activity Inventory'!B11="","",'Step 2- Activity Inventory'!B11) | C8: =IF('Step 2- Activity Inventory'!C11="","",'Step 2- Activity Inventory'!C11) | D8: =IF('Step 2- Activity Inventory'!E11="","",'Step 2- Activity Inventory'!E11) | E8: =IF('Step 2- Activity Inventory'!F11="","",'Step 2- Activity Inventory'!F11) | F8: =IF(E8="Genius","N/A",IF('Step 2- Activity Inventory'!G11="","",'Step 2- Activity Inventory'!G11)) | G8: =IF('Step 2- Activity Inventory'!D11="","",'Step 2- Activity Inventory'!D11) | L8: =IF(OR('Step 2- Activity Inventory'!O11=6,AND('Step 2- Activity Inventory'!O11=5,E8="Genius")),'Step 1- Hrly Rate Calc'!$D$18,"") | M8: =IF(B8="","",IFERROR(K8-L8,"")) | N8: =IF(L8="","",IF(IFERROR((G8/60)*M8*2*'Step 1- Hrly Rate Calc'!$D$14,"")<0,"N/A",IFERROR((G8/60)*M8*2*'Step 1- Hrly Rate Calc'!$D$14,""))) | O8: =IF(E8="Genius","KEEP DOING",IF(L8="","",IF(K8>(L8*0.75),"KEEP DOING","STOP DOING"))) | P8: =IF(L8="","",IF(O8="STOP DOING",IF(J8="Yes","Ready to Stop Doing","Not Ready"),"N/A"))
B9: =IF('Step 2- Activity Inventory'!B12="","",'Step 2- Activity Inventory'!B12) | C9: =IF('Step 2- Activity Inventory'!C12="","",'Step 2- Activity Inventory'!C12) | D9: =IF('Step 2- Activity Inventory'!E12="","",'Step 2- Activity Inventory'!E12) | E9: =IF('Step 2- Activity Inventory'!F12="","",'Step 2- Activity Inventory'!F12) | F9: =IF(E9="Genius","N/A",IF('Step 2- Activity Inventory'!G12="","",'Step 2- Activity Inventory'!G12)) | G9: =IF('Step 2- Activity Inventory'!D12="","",'Step 2- Activity Inventory'!D12) | L9: =IF(OR('Step 2- Activity Inventory'!O12=6,AND('Step 2- Activity Inventory'!O12=5,E9="Genius")),'Step 1- Hrly Rate Calc'!$D$18,"") | M9: =IF(B9="","",IFERROR(K9-L9,"")) | N9: =IF(L9="","",IF(IFERROR((G9/60)*M9*2*'Step 1- Hrly Rate Calc'!$D$14,"")<0,"N/A",IFERROR((G9/60)*M9*2*'Step 1- Hrly Rate Calc'!$D$14,""))) | O9: =IF(E9="Genius","KEEP DOING",IF(L9="","",IF(K9>(L9*0.75),"KEEP DOING","STOP DOING"))) | P9: =IF(L9="","",IF(O9="STOP DOING",IF(J9="Yes","Ready to Stop Doing","Not Ready"),"N/A"))
B10: =IF('Step 2- Activity Inventory'!B13="","",'Step 2- Activity Inventory'!B13) | C10: =IF('Step 2- Activity Inventory'!C13="","",'Step 2- Activity Inventory'!C13) | D10: =IF('Step 2- Activity Inventory'!E13="","",'Step 2- Activity Inventory'!E13) | E10: =IF('Step 2- Activity Inventory'!F13="","",'Step 2- Activity Inventory'!F13) | F10: =IF(E10="Genius","N/A",IF('Step 2- Activity Inventory'!G13="","",'Step 2- Activity Inventory'!G13)) | G10: =IF('Step 2- Activity Inventory'!D13="","",'Step 2- Activity Inventory'!D13) | L10: =IF(OR('Step 2- Activity Inventory'!O13=6,AND('Step 2- Activity Inventory'!O13=5,E10="Genius")),'Step 1- Hrly Rate Calc'!$D$18,"") | M10: =IF(B10="","",IFERROR(K10-L10,"")) | N10: =IF(L10="","",IF(IFERROR((G10/60)*M10*2*'Step 1- Hrly Rate Calc'!$D$14,"")<0,"N/A",IFERROR((G10/60)*M10*2*'Step 1- Hrly Rate Calc'!$D$14,""))) | O10: =IF(E10="Genius","KEEP DOING",IF(L10="","",IF(K10>(L10*0.75),"KEEP DOING","STOP DOING"))) | P10: =IF(L10="","",IF(O10="STOP DOING",IF(J10="Yes","Ready to Stop Doing","Not Ready"),"N/A"))
B11: =IF('Step 2- Activity Inventory'!B14="","",'Step 2- Activity Inventory'!B14) | C11: =IF('Step 2- Activity Inventory'!C14="","",'Step 2- Activity Inventory'!C14) | D11: =IF('Step 2- Activity Inventory'!E14="","",'Step 2- Activity Inventory'!E14) | E11: =IF('Step 2- Activity Inventory'!F14="","",'Step 2- Activity Inventory'!F14) | F11: =IF(E11="Genius","N/A",IF('Step 2- Activity Inventory'!G14="","",'Step 2- Activity Inventory'!G14)) | G11: =IF('Step 2- Activity Inventory'!D14="","",'Step 2- Activity Inventory'!D14) | L11: =IF(OR('Step 2- Activity Inventory'!O14=6,AND('Step 2- Activity Inventory'!O14=5,E11="Genius")),'Step 1- Hrly Rate Calc'!$D$18,"") | M11: =IF(B11="","",IFERROR(K11-L11,"")) | N11: =IF(L11="","",IF(IFERROR((G11/60)*M11*2*'Step 1- Hrly Rate Calc'!$D$14,"")<0,"N/A",IFERROR((G11/60)*M11*2*'Step 1- Hrly Rate Calc'!$D$14,""))) | O11: =IF(E11="Genius","KEEP DOING",IF(L11="","",IF(K11>(L11*0.75),"KEEP DOING","STOP DOING"))) | P11: =IF(L11="","",IF(O11="STOP DOING",IF(J11="Yes","Ready to Stop Doing","Not Ready"),"N/A"))
B12: =IF('Step 2- Activity Inventory'!B15="","",'Step 2- Activity Inventory'!B15) | C12: =IF('Step 2- Activity Inventory'!C15="","",'Step 2- Activity Inventory'!C15) | D12: =IF('Step 2- Activity Inventory'!E15="","",'Step 2- Activity Inventory'!E15) | E12: =IF('Step 2- Activity Inventory'!F15="","",'Step 2- Activity Inventory'!F15) | F12: =IF(E12="Genius","N/A",IF('Step 2- Activity Inventory'!G15="","",'Step 2- Activity Inventory'!G15)) | G12: =IF('Step 2- Activity Inventory'!D15="","",'Step 2- Activity Inventory'!D15) | L12: =IF(OR('Step 2- Activity Inventory'!O15=6,AND('Step 2- Activity Inventory'!O15=5,E12="Genius")),'Step 1- Hrly Rate Calc'!$D$18,"") | M12: =IF(B12="","",IFERROR(K12-L12,"")) | N12: =IF(L12="","",IF(IFERROR((G12/60)*M12*2*'Step 1- Hrly Rate Calc'!$D$14,"")<0,"N/A",IFERROR((G12/60)*M12*2*'Step 1- Hrly Rate Calc'!$D$14,""))) | O12: =IF(E12="Genius","KEEP DOING",IF(L12="","",IF(K12>(L12*0.75),"KEEP DOING","STOP DOING"))) | P12: =IF(L12="","",IF(O12="STOP DOING",IF(J12="Yes","Ready to Stop Doing","Not Ready"),"N/A"))
B13: =IF('Step 2- Activity Inventory'!B16="","",'Step 2- Activity Inventory'!B16) | C13: =IF('Step 2- Activity Inventory'!C16="","",'Step 2- Activity Inventory'!C16) | D13: =IF('Step 2- Activity Inventory'!E16="","",'Step 2- Activity Inventory'!E16) | E13: =IF('Step 2- Activity Inventory'!F16="","",'Step 2- Activity Inventory'!F16) | F13: =IF(E13="Genius","N/A",IF('Step 2- Activity Inventory'!G16="","",'Step 2- Activity Inventory'!G16)) | G13: =IF('Step 2- Activity Inventory'!D16="","",'Step 2- Activity Inventory'!D16) | L13: =IF(OR('Step 2- Activity Inventory'!O16=6,AND('Step 2- Activity Inventory'!O16=5,E13="Genius")),'Step 1- Hrly Rate Calc'!$D$18,"") | M13: =IF(B13="","",IFERROR(K13-L13,"")) | N13: =IF(L13="","",IF(IFERROR((G13/60)*M13*2*'Step 1- Hrly Rate Calc'!$D$14,"")<0,"N/A",IFERROR((G13/60)*M13*2*'Step 1- Hrly Rate Calc'!$D$14,""))) | O13: =IF(E13="Genius","KEEP DOING",IF(L13="","",IF(K13>(L13*0.75),"KEEP DOING","STOP DOING"))) | P13: =IF(L13="","",IF(O13="STOP DOING",IF(J13="Yes","Ready to Stop Doing","Not Ready"),"N/A"))
B14: =IF('Step 2- Activity Inventory'!B17="","",'Step 2- Activity Inventory'!B17) | C14: =IF('Step 2- Activity Inventory'!C17="","",'Step 2- Activity Inventory'!C17) | D14: =IF('Step 2- Activity Inventory'!E17="","",'Step 2- Activity Inventory'!E17) | E14: =IF('Step 2- Activity Inventory'!F17="","",'Step 2- Activity Inventory'!F17) | F14: =IF(E14="Genius","N/A",IF('Step 2- Activity Inventory'!G17="","",'Step 2- Activity Inventory'!G17)) | G14: =IF('Step 2- Activity Inventory'!D17="","",'Step 2- Activity Inventory'!D17) | L14: =IF(OR('Step 2- Activity Inventory'!O17=6,AND('Step 2- Activity Inventory'!O17=5,E14="Genius")),'Step 1- Hrly Rate Calc'!$D$18,"") | M14: =IF(B14="","",IFERROR(K14-L14,"")) | N14: =IF(L14="","",IF(IFERROR((G14/60)*M14*2*'Step 1- Hrly Rate Calc'!$D$14,"")<0,"N/A",IFERROR((G14/60)*M14*2*'Step 1- Hrly Rate Calc'!$D$14,""))) | O14: =IF(E14="Genius","KEEP DOING",IF(L14="","",IF(K14>(L14*0.75),"KEEP DOING","STOP DOING"))) | P14: =IF(L14="","",IF(O14="STOP DOING",IF(J14="Yes","Ready to Stop Doing","Not Ready"),"N/A"))
B15: =IF('Step 2- Activity Inventory'!B18="","",'Step 2- Activity Inventory'!B18) | C15: =IF('Step 2- Activity Inventory'!C18="","",'Step 2- Activity Inventory'!C18) | D15: =IF('Step 2- Activity Inventory'!E18="","",'Step 2- Activity Inventory'!E18) | E15: =IF('Step 2- Activity Inventory'!F18="","",'Step 2- Activity Inventory'!F18) | F15: =IF(E15="Genius","N/A",IF('Step 2- Activity Inventory'!G18="","",'Step 2- Activity Inventory'!G18)) | G15: =IF('Step 2- Activity Inventory'!D18="","",'Step 2- Activity Inventory'!D18) | L15: =IF(OR('Step 2- Activity Inventory'!O18=6,AND('Step 2- Activity Inventory'!O18=5,E15="Genius")),'Step 1- Hrly Rate Calc'!$D$18,"") | M15: =IF(B15="","",IFERROR(K15-L15,"")) | N15: =IF(L15="","",IF(IFERROR((G15/60)*M15*2*'Step 1- Hrly Rate Calc'!$D$14,"")<0,"N/A",IFERROR((G15/60)*M15*2*'Step 1- Hrly Rate Calc'!$D$14,""))) | O15: =IF(E15="Genius","KEEP DOING",IF(L15="","",IF(K15>(L15*0.75),"KEEP DOING","STOP DOING"))) | P15: =IF(L15="","",IF(O15="STOP DOING",IF(J15="Yes","Ready to Stop Doing","Not Ready"),"N/A"))
B16: =IF('Step 2- Activity Inventory'!B19="","",'Step 2- Activity Inventory'!B19) | C16: =IF('Step 2- Activity Inventory'!C19="","",'Step 2- Activity Inventory'!C19) | D16: =IF('Step 2- Activity Inventory'!E19="","",'Step 2- Activity Inventory'!E19) | E16: =IF('Step 2- Activity Inventory'!F19="","",'Step 2- Activity Inventory'!F19) | F16: =IF(E16="Genius","N/A",IF('Step 2- Activity Inventory'!G19="","",'Step 2- Activity Inventory'!G19)) | G16: =IF('Step 2- Activity Inventory'!D19="","",'Step 2- Activity Inventory'!D19) | L16: =IF(OR('Step 2- Activity Inventory'!O19=6,AND('Step 2- Activity Inventory'!O19=5,E16="Genius")),'Step 1- Hrly Rate Calc'!$D$18,"") | M16: =IF(B16="","",IFERROR(K16-L16,"")) | N16: =IF(L16="","",IF(IFERROR((G16/60)*M16*2*'Step 1- Hrly Rate Calc'!$D$14,"")<0,"N/A",IFERROR((G16/60)*M16*2*'Step 1- Hrly Rate Calc'!$D$14,""))) | O16: =IF(E16="Genius","KEEP DOING",IF(L16="","",IF(K16>(L16*0.75),"KEEP DOING","STOP DOING"))) | P16: =IF(L16="","",IF(O16="STOP DOING",IF(J16="Yes","Ready to Stop Doing","Not Ready"),"N/A"))
B17: =IF('Step 2- Activity Inventory'!B20="","",'Step 2- Activity Inventory'!B20) | C17: =IF('Step 2- Activity Inventory'!C20="","",'Step 2- Activity Inventory'!C20) | D17: =IF('Step 2- Activity Inventory'!E20="","",'Step 2- Activity Inventory'!E20) | E17: =IF('Step 2- Activity Inventory'!F20="","",'Step 2- Activity Inventory'!F20) | F17: =IF(E17="Genius","N/A",IF('Step 2- Activity Inventory'!G20="","",'Step 2- Activity Inventory'!G20)) | G17: =IF('Step 2- Activity Inventory'!D20="","",'Step 2- Activity Inventory'!D20) | L17: =IF(OR('Step 2- Activity Inventory'!O20=6,AND('Step 2- Activity Inventory'!O20=5,E17="Genius")),'Step 1- Hrly Rate Calc'!$D$18,"") | M17: =IF(B17="","",IFERROR(K17-L17,"")) | N17: =IF(L17="","",IF(IFERROR((G17/60)*M17*2*'Step 1- Hrly Rate Calc'!$D$14,"")<0,"N/A",IFERROR((G17/60)*M17*2*'Step 1- Hrly Rate Calc'!$D$14,""))) | O17: =IF(E17="Genius","KEEP DOING",IF(L17="","",IF(K17>(L17*0.75),"KEEP DOING","STOP DOING"))) | P17: =IF(L17="","",IF(O17="STOP DOING",IF(J17="Yes","Ready to Stop Doing","Not Ready"),"N/A"))
B18: =IF('Step 2- Activity Inventory'!B21="","",'Step 2- Activity Inventory'!B21) | C18: =IF('Step 2- Activity Inventory'!C21="","",'Step 2- Activity Inventory'!C21) | D18: =IF('Step 2- Activity Inventory'!E21="","",'Step 2- Activity Inventory'!E21) | E18: =IF('Step 2- Activity Inventory'!F21="","",'Step 2- Activity Inventory'!F21) | F18: =IF(E18="Genius","N/A",IF('Step 2- Activity Inventory'!G21="","",'Step 2- Activity Inventory'!G21)) | G18: =IF('Step 2- Activity Inventory'!D21="","",'Step 2- Activity Inventory'!D21) | L18: =IF(OR('Step 2- Activity Inventory'!O21=6,AND('Step 2- Activity Inventory'!O21=5,E18="Genius")),'Step 1- Hrly Rate Calc'!$D$18,"") | M18: =IF(B18="","",IFERROR(K18-L18,"")) | N18: =IF(L18="","",IF(IFERROR((G18/60)*M18*2*'Step 1- Hrly Rate Calc'!$D$14,"")<0,"N/A",IFERROR((G18/60)*M18*2*'Step 1- Hrly Rate Calc'!$D$14,""))) | O18: =IF(E18="Genius","KEEP DOING",IF(L18="","",IF(K18>(L18*0.75),"KEEP DOING","STOP DOING"))) | P18: =IF(L18="","",IF(O18="STOP DOING",IF(J18="Yes","Ready to Stop Doing","Not Ready"),"N/A"))
B19: =IF('Step 2- Activity Inventory'!B22="","",'Step 2- Activity Inventory'!B22) | C19: =IF('Step 2- Activity Inventory'!C22="","",'Step 2- Activity Inventory'!C22) | D19: =IF('Step 2- Activity Inventory'!E22="","",'Step 2- Activity Inventory'!E22) | E19: =IF('Step 2- Activity Inventory'!F22="","",'Step 2- Activity Inventory'!F22) | F19: =IF(E19="Genius","N/A",IF('Step 2- Activity Inventory'!G22="","",'Step 2- Activity Inventory'!G22)) | G19: =IF('Step 2- Activity Inventory'!D22="","",'Step 2- Activity Inventory'!D22) | L19: =IF(OR('Step 2- Activity Inventory'!O22=6,AND('Step 2- Activity Inventory'!O22=5,E19="Genius")),'Step 1- Hrly Rate Calc'!$D$18,"") | M19: =IF(B19="","",IFERROR(K19-L19,"")) | N19: =IF(L19="","",IF(IFERROR((G19/60)*M19*2*'Step 1- Hrly Rate Calc'!$D$14,"")<0,"N/A",IFERROR((G19/60)*M19*2*'Step 1- Hrly Rate Calc'!$D$14,""))) | O19: =IF(E19="Genius","KEEP DOING",IF(L19="","",IF(K19>(L19*0.75),"KEEP DOING","STOP DOING"))) | P19: =IF(L19="","",IF(O19="STOP DOING",IF(J19="Yes","Ready to Stop Doing","Not Ready"),"N/A"))
... B500: =IF('Step 2- Activity Inventory'!B503="","",'Step 2- Activity Inventory'!B503) | C500: =IF('Step 2- Activity Inventory'!C503="","",'Step 2- Activity Inventory'!C503) | D500: =IF('Step 2- Activity Inventory'!E503="","",'Step 2- Activity Inventory'!E503) | E500: =IF('Step 2- Activity Inventory'!F503="","",'Step 2- Activity Inventory'!F503) | F500: =IF(E500="Genius","N/A",IF('Step 2- Activity Inventory'!G503="","",'Step 2- Activity Inventory'!G503)) | G500: =IF('Step 2- Activity Inventory'!D503="","",'Step 2- Activity Inventory'!D503) | L500: =IF(OR('Step 2- Activity Inventory'!O503=6,AND('Step 2- Activity Inventory'!O503=5,E500="Genius")),'Step 1- Hrly Rate Calc'!$D$18,"") | M500: =IF(B500="","",IFERROR(K500-L500,"")) | N500: =IF(L500="","",IF(IFERROR((G500/60)*M500*2*'Step 1- Hrly Rate Calc'!$D$14,"")<0,"N/A",IFERROR((G500/60)*M500*2*'Step 1- Hrly Rate Calc'!$D$14,""))) | O500: =IF(E500="Genius","KEEP DOING",IF(L500="","",IF(K500>(L500*0.75),"KEEP DOING","STOP DOING"))) | P500: =IF(L500="","",IF(O500="STOP DOING",IF(J500="Yes","Ready to Stop Doing","Not Ready"),"N/A"))

Sheet Temp
